<robot name="ElevenLinkHuman">

    <link name="right_foot">
        <inertial>
            <mass value="FOOTMASS"/>
            <origin xyz="0 0 HALFFOOT_BETA" rpy="0 0 0" />
            <inertia ixx="FOOTINERTIAIXX" iyy="FOOTINERTIAIYY" izz="FOOTINERTIAIZZ" ixy="0" ixz="0" iyz="0"/>
        </inertial>

        <visual>
	    <origin xyz="0 0 HALFFOOT_BETA" rpy="0 0 0" />
            <geometry>
                <box size="FOOTGAMMA FOOTALFA FOOTBETA"/>
            </geometry>
        </visual>

        <collision>
	    <origin xyz="0 0 HALFFOOT_BETA" rpy="0 0 0" />
            <geometry>
                <box size="FOOTGAMMA FOOTALFA FOOTBETA"/>
            </geometry>
        </collision>
    </link>

 
    <link name="right_lowerleg">
        <inertial>
            <mass value="LOWERLEGMASS"/>
            <origin xyz="0 0 HALFLOWERLEG_HEIGTH" rpy="0 0 0" />
            <inertia ixx="LOWERLEGINERTIAIXX" iyy="LOWERLEGINERTIAIYY" izz="LOWERLEGINERTIAIZZ" ixy="0" ixz="0" iyz="0"/>
        </inertial>

        <visual>
            <origin xyz="0 0 HALFLOWERLEG_HEIGTH" rpy="0 0 0" />
            <geometry>
		<cylinder length="LOWERLEGHEIGTH" radius="LOWERLEGRADIUS"/>
            </geometry>
        </visual>

        <collision>
            <origin xyz="0 0 HALFLOWERLEG_HEIGTH" rpy="0 0 0" />
            <geometry>
                <cylinder length="LOWERLEGHEIGTH" radius="LOWERLEGRADIUS"/>
            </geometry>
        </collision>
    </link>
    

    <link name="right_upperleg">
        <inertial>
            <mass value="UPPERLEGMASS"/>
            <origin xyz="0 0 HALFUPPERLEG_HEIGTH" rpy="0 0 0" />
            <inertia ixx="UPPERLEGINERTIAIXX" iyy="UPPERLEGINERTIAIYY" izz="UPPERLEGINERTIAIZZ" ixy="0" ixz="0" iyz="0"/>
        </inertial>

        <visual>
            <origin xyz="0 0 HALFUPPERLEG_HEIGTH" rpy="0 0 0" />
            <geometry>
                <cylinder length="UPPERLEGHEIGTH" radius="UPPERLEGRADIUS"/>
            </geometry>
        </visual>

        <collision>
            <origin xyz="0 0 HALFUPPERLEG_HEIGTH" rpy="0 0 0" />
            <geometry>
                <cylinder length="UPPERLEGHEIGTH" radius="UPPERLEGRADIUS"/>
            </geometry>
        </collision>
    </link>

	
    <link name="left_upperleg">
        <inertial>
            <mass value="UPPERLEGMASS"/>
            <origin xyz="0 0 -HALFUPPERLEG_HEIGTH" rpy="0 0 0" />
            <inertia ixx="UPPERLEGINERTIAIXX" iyy="UPPERLEGINERTIAIYY" izz="UPPERLEGINERTIAIZZ" ixy="0" ixz="0" iyz="0"/>
        </inertial>

        <visual>
            <origin xyz="0 0 -HALFUPPERLEG_HEIGTH" rpy="0 0 0" />
            <geometry>
                <cylinder length="UPPERLEGHEIGTH" radius="UPPERLEGRADIUS"/>
            </geometry>
        </visual>

        <collision>
            <origin xyz="0 0 -HALFUPPERLEG_HEIGTH" rpy="0 0 0" />
            <geometry>
                <cylinder length="UPPERLEGHEIGTH" radius="UPPERLEGRADIUS"/>
            </geometry>
        </collision>
    </link>


    <link name="left_lowerleg">
        <inertial>
            <mass value="LOWERLEGMASS"/>
            <origin xyz="0 0 -HALFLOWERLEG_HEIGTH" rpy="0 0 0" />
            <inertia ixx="LOWERLEGINERTIAIXX" iyy="LOWERLEGINERTIAIYY" izz="LOWERLEGINERTIAIZZ" ixy="0" ixz="0" iyz="0"/>
        </inertial>

        <visual>
            <origin xyz="0 0 -HALFLOWERLEG_HEIGTH" rpy="0 0 0" />
            <geometry>
                <cylinder length="LOWERLEGHEIGTH" radius="LOWERLEGRADIUS"/>
            </geometry>
        </visual>

        <collision>
            <origin xyz="0 0 -HALFLOWERLEG_HEIGTH" rpy="0 0 0" />
            <geometry>
                <cylinder length="LOWERLEGHEIGTH" radius="LOWERLEGRADIUS"/>
            </geometry>
        </collision>
    </link>


    <link name="left_foot">
        <inertial>
            <mass value="FOOTMASS"/>
            <origin xyz="ANKLEPOSITION 0 -HALFFOOT_BETA" rpy="0 0 0" />
            <inertia ixx="FOOTINERTIAIXX" iyy="FOOTINERTIAIYY" izz="FOOTINERTIAIZZ" ixy="0" ixz="0" iyz="0"/>
        </inertial>

        <visual>
	    <origin xyz="ANKLEPOSITION 0 -HALFFOOT_BETA" rpy="0 0 0" />
            <geometry>
                <box size="FOOTGAMMA FOOTALFA FOOTBETA"/>
            </geometry>
        </visual>

        <collision>
	    <origin xyz="ANKLEPOSITION 0 -HALFFOOT_BETA" rpy="0 0 0" />
            <geometry>
                <box size="FOOTGAMMA FOOTALFA FOOTBETA"/>
            </geometry>
        </collision>
    </link>


    <link name="torso">
        <inertial>
            <mass value="TORSOMASS"/>
            <origin xyz="0 MIDTORSOPOSITION HALFTORSO_BETA" rpy="0 0 0" />
            <inertia ixx="TORSOINERTIAIXX" iyy="TORSOINERTIAIYY" izz="TORSOINERTIAIZZ" ixy="0" ixz="0" iyz="0"/>
        </inertial>

        <visual>
            <origin xyz="0 MIDTORSOPOSITION HALFTORSO_BETA" rpy="0 0 0" />
            <geometry>
                <box size="TORSOGAMMA TORSOALFA TORSOBETA"/>
            </geometry>
        </visual>

        <collision>
            <origin xyz="0 MIDTORSOPOSITION HALFTORSO_BETA" rpy="0 0 0" />
            <geometry>
                <box size="TORSOGAMMA TORSOALFA TORSOBETA"/>
            </geometry>
        </collision>
    </link>
        

    <link name="right_upperarm">
        <inertial>
            <mass value="UPPERARMMASS"/>
            <origin xyz="0 -UPPERARMRADIUS -SHOULDERPOSITION" rpy="0 0 0" />
            <inertia ixx="UPPERARMINERTIAIXX" iyy="UPPERARMINERTIAIYY" izz="UPPERARMINERTIAIZZ" ixy="0" ixz="0" iyz="0"/>
        </inertial>

        <visual>
            <origin xyz="0 -UPPERARMRADIUS -SHOULDERPOSITION" rpy="0 0 0" />
            <geometry>
                <cylinder length="UPPERARMHEIGTH" radius="UPPERARMRADIUS"/>
            </geometry>
        </visual>

        <collision>
            <origin xyz="0 -UPPERARMRADIUS -SHOULDERPOSITION" rpy="0 0 0" />
            <geometry>
                <cylinder length="UPPERARMHEIGTH" radius="UPPERARMRADIUS"/>
            </geometry>
        </collision>
    </link>

    <link name="left_upperarm">
        <inertial>
            <mass value="UPPERARMMASS"/>
            <origin xyz="0 UPPERARMRADIUS -SHOULDERPOSITION" rpy="0 0 0" />
            <inertia ixx="UPPERARMINERTIAIXX" iyy="UPPERARMINERTIAIYY" izz="UPPERARMINERTIAIZZ" ixy="0" ixz="0" iyz="0"/>
        </inertial>

        <visual>
            <origin xyz="0 UPPERARMRADIUS -SHOULDERPOSITION" rpy="0 0 0" />
            <geometry>
                <cylinder length="UPPERARMHEIGTH" radius="UPPERARMRADIUS"/>
            </geometry>
        </visual>

        <collision>
            <origin xyz="0 UPPERARMRADIUS -SHOULDERPOSITION" rpy="0 0 0" />
            <geometry>
                <cylinder length="UPPERARMHEIGTH" radius="UPPERARMRADIUS"/>
            </geometry>
        </collision>
    </link>

    <link name="right_lowerarm">
        <inertial>
            <mass value="LOWERARMMASS"/>
            <origin xyz="0 0 -HALFLOWERARM_HEIGTH" rpy="0 0 0" />
            <inertia ixx="LOWERARMINERTIAIXX" iyy="LOWERARMINERTIAIYY" izz="LOWERARMINERTIAIZZ" ixy="0" ixz="0" iyz="0"/>
        </inertial>

        <visual>
            <origin xyz="0 0 -HALFLOWERARM_HEIGTH" rpy="0 0 0" />
            <geometry>
                <cylinder length="LOWERARMHEIGTH" radius="LOWERARMRADIUS"/>
            </geometry>
        </visual>

        <collision>
            <origin xyz="0 0 -HALFLOWERARM_HEIGTH" rpy="0 0 0" />
            <geometry>
                <cylinder length="LOWERARMHEIGTH" radius="LOWERARMRADIUS"/>
            </geometry>
        </collision>
    </link>

    <link name="left_lowerarm">
        <inertial>
            <mass value="LOWERARMMASS"/>
            <origin xyz="0 0 -HALFLOWERARM_HEIGTH" rpy="0 0 0" />
            <inertia ixx="LOWERARMINERTIAIXX" iyy="LOWERARMINERTIAIYY" izz="LOWERARMINERTIAIZZ" ixy="0" ixz="0" iyz="0"/>
        </inertial>

        <visual>
            <origin xyz="0 0 -HALFLOWERARM_HEIGTH" rpy="0 0 0" />
            <geometry>
                <cylinder length="LOWERARMHEIGTH" radius="LOWERARMRADIUS"/>
            </geometry>
        </visual>

        <collision>
            <origin xyz="0 0 -HALFLOWERARM_HEIGTH" rpy="0 0 0" />
            <geometry>
                <cylinder length="LOWERARMHEIGTH" radius="LOWERARMRADIUS"/>
            </geometry>
        </collision>
    </link>


    <link name="head">
        <inertial>
            <mass value="HEADMASS"/>
            <origin xyz="0 0 HEADRADIUS" rpy="0 0 0" />
            <inertia ixx="HEADINERTIAIXX" iyy="HEADINERTIAIYY" izz="HEADINERTIAIZZ" ixy="0" ixz="0" iyz="0"/>
        </inertial>

        <visual>
            <origin xyz="0 0 HEADRADIUS" rpy="0 0 0" />
            <geometry>
                <sphere radius="HEADRADIUS"/>
            </geometry>
        </visual>

        <collision>
            <origin xyz="0 0 HEADRADIUS" rpy="0 0 0" />
            <geometry>
                <sphere radius="HEADRADIUS"/>
            </geometry>
        </collision>
    </link>
        

    <joint name="right_ankle" type="revolute">
        <origin xyz="-ANKLEPOSITION 0 FOOTBETA" rpy="0 0 0"/>
        <parent link="right_foot"/>
        <child link="right_lowerleg"/>
        <dynamics damping="0.1" friction="0.0"/>
        <limit effort="30" velocity="1.0" lower="-10.0" upper="10.0" />
        <axis xyz="0 1 0" />
    </joint>


    <joint name="right_knee" type="revolute">
        <origin xyz="0 0 LOWERLEGHEIGTH" rpy="0 0 0"/>
        <parent link="right_lowerleg"/>
        <child link="right_upperleg"/>
        <dynamics damping="0.1" friction="0.0"/>
        <limit effort="30" velocity="1.0" lower="-10.0" upper="10.0" />
        <axis xyz="0 1 0" />
    </joint>
    
	
    <joint name="right_hip" type="revolute">
        <origin xyz="0 0 UPPERLEGHEIGTH" rpy="0 0 0"/>
        <parent link="right_upperleg"/>
        <child link="torso"/>
        <dynamics damping="0.1" friction="0.0"/>
        <limit effort="30" velocity="1.0" lower="-10.0" upper="10.0" />
        <axis xyz="0 1 0" />
    </joint>

	
    <joint name="left_hip" type="revolute">
        <origin xyz="0 LEFTHIPPOSITION 0" rpy="0 0 0"/>
        <parent link="torso"/>
        <child link="left_upperleg"/>
        <dynamics damping="0.1" friction="0.0"/>
        <limit effort="30" velocity="1.0" lower="-10.0" upper="10.0" />
        <axis xyz="0 1 0" />
    </joint>


    <joint name="left_knee" type="revolute">
        <origin xyz="0 0 -UPPERLEGHEIGTH" rpy="0 0 0"/>
        <parent link="left_upperleg"/>
        <child link="left_lowerleg"/>
        <dynamics damping="0.1" friction="0.0"/>
        <limit effort="30" velocity="1.0" lower="-10.0" upper="10.0" />
        <axis xyz="0 1 0" />
    </joint>


    <joint name="left_ankle" type="revolute">
        <origin xyz="0 0 -LOWERLEGHEIGTH" rpy="0 0 0"/>
        <parent link="left_lowerleg"/>
        <child link="left_foot"/>
        <dynamics damping="0.1" friction="0.0"/>
        <limit effort="30" velocity="1.0" lower="-10.0" upper="10.0" />
        <axis xyz="0 1 0" />
    </joint>

	
    <joint name="right_shoulder" type="revolute">
        <origin xyz="0 -RIGHTSHOULDER_POSITION SHOULDERHEIGTH" rpy="0 0 0"/>
        <parent link="torso"/>
        <child link="right_upperarm"/>
        <dynamics damping="0.1" friction="0.0"/>
        <limit effort="30" velocity="1.0" lower="-10.0" upper="10.0" />
        <axis xyz="0 1 0" />
    </joint>


    <joint name="left_shoulder" type="revolute">
        <origin xyz="0 LEFTSHOULDER_POSITION SHOULDERHEIGTH" rpy="0 0 0"/>
        <parent link="torso"/>
        <child link="left_upperarm"/>
        <dynamics damping="0.1" friction="0.0"/>
        <limit effort="30" velocity="1.0" lower="-10.0" upper="10.0" />
        <axis xyz="0 1 0" />
    </joint>


    <joint name="right_elbow" type="revolute">
        <origin xyz="0 -UPPERARMRADIUS -ELBOWPOSITION" rpy="0 0 0"/>
        <parent link="right_upperarm"/>
        <child link="right_lowerarm"/>
        <dynamics damping="0.1" friction="0.0"/>
        <limit effort="30" velocity="1.0" lower="-10.0" upper="10.0" />
        <axis xyz="0 1 0" />
    </joint>


    <joint name="left_elbow" type="revolute">
        <origin xyz="0 UPPERARMRADIUS -ELBOWPOSITION" rpy="0 0 0"/>
        <parent link="left_upperarm"/>
        <child link="left_lowerarm"/>
        <dynamics damping="0.1" friction="0.0"/>
        <limit effort="30" velocity="1.0" lower="-10.0" upper="10.0" />
        <axis xyz="0 1 0" />
    </joint>


    <joint name="neck" type="revolute">
        <origin xyz="0 MIDTORSOPOSITION TORSOBETA" rpy="0 0 0"/>
        <parent link="torso"/>
        <child link="head"/>
        <dynamics damping="0.1" friction="0.0"/>
        <limit effort="30" velocity="1.0" lower="-10.0" upper="10.0" />
        <axis xyz="0 0 1" />
    </joint>

</robot>
